0 / 1 epoches
Evaluation on esposalles_dataset_test
3
Traceback (most recent call last):
  File "/home/amolina/oda_ocr/main.py", line 112, in <module>
    main(args)
  File "/home/amolina/oda_ocr/main.py", line 107, in main
    loop(args.epoches, model, datasets, collator, tokenizer, args)
  File "/home/amolina/oda_ocr/main.py", line 73, in loop
    evals = evaluation_epoch(datasets, model, tokenizer, collator, args)
  File "/home/amolina/oda_ocr/main.py", line 61, in evaluation_epoch
    eval_dataset(dataloader, model, dataset_name, tokenizer, wandb)
  File "/home/amolina/oda_ocr/src/evaluation/eval.py", line 20, in eval_dataset
    for batch in dataloader:
  File "/home/amolina/miniconda3/envs/oda/lib/python3.9/site-packages/torch/utils/data/dataloader.py", line 628, in __next__
    data = self._next_data()
  File "/home/amolina/miniconda3/envs/oda/lib/python3.9/site-packages/torch/utils/data/dataloader.py", line 1333, in _next_data
    return self._process_data(data)
  File "/home/amolina/miniconda3/envs/oda/lib/python3.9/site-packages/torch/utils/data/dataloader.py", line 1359, in _process_data
    data.reraise()
  File "/home/amolina/miniconda3/envs/oda/lib/python3.9/site-packages/torch/_utils.py", line 543, in reraise
    raise exception
KeyError: Caught KeyError in DataLoader worker process 0.
Original Traceback (most recent call last):
  File "/home/amolina/miniconda3/envs/oda/lib/python3.9/site-packages/torch/utils/data/_utils/worker.py", line 302, in _worker_loop
    data = fetcher.fetch(index)
  File "/home/amolina/miniconda3/envs/oda/lib/python3.9/site-packages/torch/utils/data/_utils/fetch.py", line 58, in fetch
    data = [self.dataset[idx] for idx in possibly_batched_index]
  File "/home/amolina/miniconda3/envs/oda/lib/python3.9/site-packages/torch/utils/data/_utils/fetch.py", line 58, in <listcomp>
    data = [self.dataset[idx] for idx in possibly_batched_index]
KeyError: 0